<?xml version="1.0" encoding="utf-8"?>
<!-- This URDF was automatically created by SolidWorks to URDF Exporter! Originally created by Stephen Brawner (brawner@gmail.com) 
     Commit Version: 1.6.0-4-g7f85cfe  Build Version: 1.6.7995.38578
     For more information, please see http://wiki.ros.org/sw_urdf_exporter -->
<robot
  name="robot_urdf">
  <link
    name="base_link">
    <inertial>
      <origin
        xyz="9.0203E-08 0.073791 -0.019069"
        rpy="0 0 0" />
      <mass
        value="10.753" />
      <inertia
        ixx="0.019849"
        ixy="6.5381E-10"
        ixz="2.5647E-09"
        iyy="0.038526"
        iyz="5.2628E-05"
        izz="0.023738" />
    </inertial>
    <visual>
      <origin
        xyz="0 0 0"
        rpy="0 0 0" />
      <geometry>
        <mesh
          filename="package://robot_urdf/meshes/base_link.STL" />
      </geometry>
      <material
        name="">
        <color
          rgba="0.59216 0.61961 0.65098 1" />
      </material>
    </visual>
    <collision>
      <origin
        xyz="0 0 0"
        rpy="0 0 0" />
      <geometry>
        <mesh
          filename="package://robot_urdf/meshes/base_link.STL" />
      </geometry>
    </collision>
  </link>
  <link
    name="link_wheel_rear_right">
    <inertial>
      <origin
        xyz="-0.17862 0.013534 0.024673"
        rpy="0 0 0" />
      <mass
        value="2.9659" />
      <inertia
        ixx="0.0036209"
        ixy="2.0673E-07"
        ixz="5.7974E-09"
        iyy="0.0036199"
        iyz="5.941E-09"
        izz="0.0063812" />
    </inertial>
    <visual>
      <origin
        xyz="0 0 0"
        rpy="0 0 0" />
      <geometry>
        <mesh
          filename="package://robot_urdf/meshes/link_wheel_rear_right.STL" />
      </geometry>
      <material
        name="">
        <color
          rgba="0.79216 0.81961 0.93333 1" />
      </material>
    </visual>
    <collision>
      <origin
        xyz="0 0 0"
        rpy="0 0 0" />
      <geometry>
        <mesh
          filename="package://robot_urdf/meshes/link_wheel_rear_right.STL" />
      </geometry>
    </collision>
  </link>
  <joint
    name="joint_wheel_rear_right"
    type="revolute">
    <origin
      xyz="-0.1571 0.094979 -0.073292"
      rpy="1.5708 0.78473 -1.5708" />
    <parent
      link="base_link" />
    <child
      link="link_wheel_rear_right" />
    <axis
      xyz="0 0 0" />
    <limit
      lower="0"
      upper="0"
      effort="0"
      velocity="0" />
  </joint>
  <link
    name="link_wheel_rear_left">
    <inertial>
      <origin
        xyz="5.6432E-08 -0.0079572 -6.9612E-08"
        rpy="0 0 0" />
      <mass
        value="0.50768" />
      <inertia
        ixx="0.00048677"
        ixy="-6.188E-10"
        ixz="-5.6106E-08"
        iyy="0.00085979"
        iyz="7.7341E-10"
        izz="0.0004867" />
    </inertial>
    <visual>
      <origin
        xyz="0 0 0"
        rpy="0 0 0" />
      <geometry>
        <mesh
          filename="package://robot_urdf/meshes/link_wheel_rear_left.STL" />
      </geometry>
      <material
        name="">
        <color
          rgba="0.79216 0.81961 0.93333 1" />
      </material>
    </visual>
    <collision>
      <origin
        xyz="0 0 0"
        rpy="0 0 0" />
      <geometry>
        <mesh
          filename="package://robot_urdf/meshes/link_wheel_rear_left.STL" />
      </geometry>
    </collision>
  </link>
  <joint
    name="joint_wheel_rear_right"
    type="revolute">
    <origin
      xyz="0.1941 0.2118 0.0625"
      rpy="0 -1.454 -1.5708" />
    <parent
      link="base_link" />
    <child
      link="link_wheel_rear_left" />
    <axis
      xyz="0 0 0" />
    <limit
      lower="0"
      upper="0"
      effort="0"
      velocity="0" />
  </joint>
  <link
    name="link_steering_pinion">
    <inertial>
      <origin
        xyz="0.006 4.8572E-17 -5.3252E-11"
        rpy="0 0 0" />
      <mass
        value="0.0054889" />
      <inertia
        ixx="4.4352E-07"
        ixy="-1.2013E-22"
        ixz="-1.3836E-15"
        iyy="2.8763E-07"
        iyz="-5.294E-23"
        izz="2.8763E-07" />
    </inertial>
    <visual>
      <origin
        xyz="0 0 0"
        rpy="0 0 0" />
      <geometry>
        <mesh
          filename="package://robot_urdf/meshes/link_steering_pinion.STL" />
      </geometry>
      <material
        name="">
        <color
          rgba="0.77647 0.75686 0.73725 1" />
      </material>
    </visual>
    <collision>
      <origin
        xyz="0 0 0"
        rpy="0 0 0" />
      <geometry>
        <mesh
          filename="package://robot_urdf/meshes/link_steering_pinion.STL" />
      </geometry>
    </collision>
  </link>
  <joint
    name="joint_steering_pinion"
    type="prismatic">
    <origin
      xyz="0 -0.074 0.06955"
      rpy="2.3648 0 -1.5708" />
    <parent
      link="base_link" />
    <child
      link="link_steering_pinion" />
    <axis
      xyz="0 0 0" />
    <limit
      lower="-0.25"
      upper="0.25"
      effort="0"
      velocity="0" />
  </joint>
  <link
    name="link_steering_rack">
    <inertial>
      <origin
        xyz="-9.4E-07 -0.0087881 0.0039404"
        rpy="0 0 0" />
      <mass
        value="0.16855" />
      <inertia
        ixx="2.0872E-05"
        ixy="1.0847E-09"
        ixz="-4.9012E-09"
        iyy="0.00012304"
        iyz="5.394E-06"
        izz="0.00013502" />
    </inertial>
    <visual>
      <origin
        xyz="0 0 0"
        rpy="0 0 0" />
      <geometry>
        <mesh
          filename="package://robot_urdf/meshes/link_steering_rack.STL" />
      </geometry>
      <material
        name="">
        <color
          rgba="0.96863 0.25882 0.25882 1" />
      </material>
    </visual>
    <collision>
      <origin
        xyz="0 0 0"
        rpy="0 0 0" />
      <geometry>
        <mesh
          filename="package://robot_urdf/meshes/link_steering_rack.STL" />
      </geometry>
    </collision>
  </link>
  <joint
    name="joint_steering_rack"
    type="floating">
    <origin
      xyz="0.006 -0.016367 0.016653"
      rpy="1.5708 0.77675 -1.5708" />
    <parent
      link="link_steering_pinion" />
    <child
      link="link_steering_rack" />
    <axis
      xyz="0 0 0" />
  </joint>
  <link
    name="link_steering_rods">
    <inertial>
      <origin
        xyz="0.060065 0.0095269 0.059552"
        rpy="0 0 0" />
      <mass
        value="0.633" />
      <inertia
        ixx="0.00024891"
        ixy="9.7727E-06"
        ixz="3.6482E-06"
        iyy="0.00026531"
        iyz="-4.0001E-05"
        izz="0.00023486" />
    </inertial>
    <visual>
      <origin
        xyz="0 0 0"
        rpy="0 0 0" />
      <geometry>
        <mesh
          filename="package://robot_urdf/meshes/link_steering_rods.STL" />
      </geometry>
      <material
        name="">
        <color
          rgba="0.96863 0.25882 0.25882 1" />
      </material>
    </visual>
    <collision>
      <origin
        xyz="0 0 0"
        rpy="0 0 0" />
      <geometry>
        <mesh
          filename="package://robot_urdf/meshes/link_steering_rods.STL" />
      </geometry>
    </collision>
  </link>
  <joint
    name="joint_steering_rods"
    type="floating">
    <origin
      xyz="-0.072482 0 -0.0094931"
      rpy="3.1416 -0.23961 0" />
    <parent
      link="link_steering_rack" />
    <child
      link="link_steering_rods" />
    <axis
      xyz="0 0 0" />
  </joint>
  <link
    name="link_lidar">
    <inertial>
      <origin
        xyz="-0.012223 2.6945E-06 -0.0080115"
        rpy="0 0 0" />
      <mass
        value="0.086273" />
      <inertia
        ixx="3.2361E-05"
        ixy="-9.951E-08"
        ixz="2.8041E-06"
        iyy="4.3879E-05"
        iyz="3.5039E-08"
        izz="6.1441E-05" />
    </inertial>
    <visual>
      <origin
        xyz="0 0 0"
        rpy="0 0 0" />
      <geometry>
        <mesh
          filename="package://robot_urdf/meshes/link_lidar.STL" />
      </geometry>
      <material
        name="">
        <color
          rgba="0.10196 0.10196 0.10196 1" />
      </material>
    </visual>
    <collision>
      <origin
        xyz="0 0 0"
        rpy="0 0 0" />
      <geometry>
        <mesh
          filename="package://robot_urdf/meshes/link_lidar.STL" />
      </geometry>
    </collision>
  </link>
  <joint
    name="joint_lidar"
    type="fixed">
    <origin
      xyz="0 -0.226 0.18304"
      rpy="3.1416 0 -1.5708" />
    <parent
      link="base_link" />
    <child
      link="link_lidar" />
    <axis
      xyz="0 0 0" />
  </joint>
  <link
    name="link_depth_camera">
    <inertial>
      <origin
        xyz="-0.00069728 -4.5196E-06 -0.01017"
        rpy="0 0 0" />
      <mass
        value="0.24743" />
      <inertia
        ixx="1.5937E-05"
        ixy="-1.7793E-08"
        ixz="-2.0407E-06"
        iyy="0.00013973"
        iyz="-1.3963E-08"
        izz="0.00014828" />
    </inertial>
    <visual>
      <origin
        xyz="0 0 0"
        rpy="0 0 0" />
      <geometry>
        <mesh
          filename="package://robot_urdf/meshes/link_depth_camera.STL" />
      </geometry>
      <material
        name="">
        <color
          rgba="0.75294 0.75294 0.75294 1" />
      </material>
    </visual>
    <collision>
      <origin
        xyz="0 0 0"
        rpy="0 0 0" />
      <geometry>
        <mesh
          filename="package://robot_urdf/meshes/link_depth_camera.STL" />
      </geometry>
    </collision>
  </link>
  <joint
    name="joint_depth_camera"
    type="fixed">
    <origin
      xyz="-0.00073135 -0.26096 0.16"
      rpy="1.5708 0 0" />
    <parent
      link="base_link" />
    <child
      link="link_depth_camera" />
    <axis
      xyz="0 0 0" />
  </joint>
  <link
    name="link_laser">
    <inertial>
      <origin
        xyz="0 0 0"
        rpy="0 0 0" />
      <mass
        value="0" />
      <inertia
        ixx="0"
        ixy="0"
        ixz="0"
        iyy="0"
        iyz="0"
        izz="0" />
    </inertial>
    <visual>
      <origin
        xyz="0 0 0"
        rpy="0 0 0" />
      <geometry>
        <mesh
          filename="package://robot_urdf/meshes/link_laser.STL" />
      </geometry>
      <material
        name="">
        <color
          rgba="1 1 1 1" />
      </material>
    </visual>
    <collision>
      <origin
        xyz="0 0 0"
        rpy="0 0 0" />
      <geometry>
        <mesh
          filename="package://robot_urdf/meshes/link_laser.STL" />
      </geometry>
    </collision>
  </link>
  <joint
    name="joint_laser"
    type="fixed">
    <origin
      xyz="0.17095 0.064159 0.077571"
      rpy="-3.1416 0 1.5708" />
    <parent
      link="base_link" />
    <child
      link="link_laser" />
    <axis
      xyz="0 0 0" />
  </joint>
</robot>